---
title: 에러 처리하기 - 3
date: 2023-02-09
categories: [C++,C++]
tags: [C++]		# TAG는 반드시 소문자로 이루어져야함!
---



익셉션 처리 과정에서 흔히 발생하는 문제
====================
* 익셉션 매커니즘을 이용해서 에러 처리할 때 흔히 발생하는 문제들이 있다.

<br>

메모리 할당 에러
----------------
* 흔히 사용하는 64비트 플랫폼에서는 이런 일이 거의 없지만, 모바일 시스템이나 레거시 시스템에서는 메모리 할당 에러가 드물지 않게 발생한다.

<br>

* new나 new[]에서 메모리를 할당할 수 없을 때 기본적으로 수행하는 동작은 \<new> 헤더 파일에 정의된 bad_alloc 익셉션을 던지낟.

* new나 new[]를 호출할 때마다 try/catch문으로 감싸도 되지만, 할당하려는 메모리 블럭의 크기가 글 때만 이렇게 하는 것이 좋다.

<br>

    // 메모리 할당 익셉션을 잡는 방법

    int* ptr = nullptr;
    size_t integerCount = numeric_limits<size_t>::max();
    try{
        ptr = new int[integerCount];
    } catch(const bad_alloc& e){
        ...
        return;
    }


<br><br><br>

익셉션을 던지지 않는 new
-------------
* 익셉션 매커니즘을 사용하지 않고, 예전 C방식처럼 메모리 할당에 실패하면 널포인트를 리턴하도록 작성해도 된다.

* C++는 익셉션을 던지지 않는 nothrow 버전의 new와 new[]도 제공한다.

<br>

    int* ptr = new(nothrow) int[integerCount];  // 익셉션을 던지지 않는 nothrow버전의 new
    if ( nullptr == ptr )
    {
        ...
        return;
    }

<br>

* nothrow는 new의 인수

<br><br><br>

메모리 할당 에러 처리 방식 커스터마이즈하기
---------------------
* C++는 new 핸들러 콜백 함수를 커스터마이즈하는 기능을 제공한다.

* 기본적으로 new나 new[]는 new핸들러를 사용하지 않고 bad_alloc 익셉션을 던진다.

<br>

* new 핸들러

  * new 핸들러를 정의하면 메모리 할당 루틴에서 에러가 발생했을 때 익셉션을 던지지 않고 정의된 new 핸들러를 호출한다.

  * new 핸들러가 리턴하면 메모리 할당 루틴은 메모리를 다시 할당하려 하는데, 실패해도 다시 new 핸들러를 호출한다.

<br>

* new 핸들러는 다음 세 가지 중 한가지 방식으로 구현하지 않으면 무한루프가 발생할 수 있다.

    * 메모리 추가하기
      * 공간 확보를 위한 한가지 방법은 프로그램 구동시 큰 덩어리의 메모리를 할당했다가 new 핸들러로 해제
      
      * ex)메모리 할당 에러가 발생하면 현재 상태를 저장하기 위해서는 new 핸들러가 호출되면 이 블록을 해제한 뒤 상태를 저장하고 프로그램을 다시 구동해서 저장된 상태를 불러온다.
    <br>

    * 익셉션 던지기
      * C++표준에서는 new 핸들러에서 익셉션을 던질 때 반드시 bad_alloc이나 이를 상속한 익셉션을 던져야 한다.
      
      * ex) bad_alloc을 상속한 document_recovery_alloc(문서 저장)
    <br>

    * 다른 new 핸들러 설정하기
      * 이론적으로 new 핸들러를 여러 개 만들어 각각 메모리를 생성하고 문제가 발생하면 다른 new 핸들러를 설정
      
      * 실제 효과에 비해 코드가 복잡하다는 단점이 있음
    
<br><br><br><br>

생성자에서 발생하는 에러
====================
* 생성자가 값을 리턴하지 못해도 익셉션을 던질 수 있다.

* 하지만 익셉션이 발생해서 생성자가 정상종료되지 않고 중간에 실행을 멈추고 빠져나와버리면 나중에 그 객체의 소멸자가 호출될 수 없다

* 따라서 익셉션이 발생해서 생성자를 빠져나올 때는 반드시 생성자에서 할당했던 메모리와 리소스를 정리해야 한다.

<br><br>

* 예시

<br>

    // 클래스 템플릿
    template <typename T>
    class Matrix
    {
        public:
            Matrix(size_t width, size_t height);
            virtual ~Matrix();
        private:
            void cleanup();

            size_t mWidth = 0;
            size_t mHeight = 0;
            T** mMatrix = nullptr;
    }


    // 생성자 구현 코드
    template<typename T>
    Matrix<T>::Matrix(size_t width, size_t height)
    {
        mMatrix = new T*[width] {}; // 초기화

        // 생성자 이니셜라이저로는 초기화하면 안됨. new가 성공적으로 할당될 때만 초기화
        mWidth = width;
        mHeight = height;

        try{
            for(size_t i = 0 ;i < width; i++){
                mMatrix[i] = new T[height];
            }
        } catch(...){   // T의 생성자에서 발생한 익셉션을 알 수 없어 모든 익셉션을 잡기위해 ...를 사용
            cleanup();
            // 발생한 익셉션을 모두 bad_alloc 익셉션 안에 중첩
            std::throw_with_nexted(std::bad_alloc());
        }
    }

<br><br><br>

생성자를 위한 try블록
=======================
* 함수 try블록이란 기능으로 익셉션을 처리
  
* 함수 try블록은 일반 함수뿐만 아니라 생성자에 적용할 수도 있다.

<br>

    MyClass::MyClass()
    try
        : <생성자 이니셜라이저>
    {
        /* 생성자 본문 */
    }
    catch (const exception& e)
    {
        / * ... */
    }

<br>

* 함수 try 블록을 적용할 때 주의할 점 <br><br>

  * catch문은 생성자 이니셜라이저나 생성자 본문에서 발생한 익셉션을 잡아서 처리한다.<br><br>
  
  * catch문은 반드시 현재 발생한 익셉션을 다시 던지거나 새 익셉션을 만들어 던져야한다.<br>
    catch문에서 이렇게 처리하지 않으면 런타임이 자동으로 현재 익셉션을 다시 던진다.<br><br>

  * catch문은 생성자에 전달된 인수에 접근할 수 있다.<br><br>

  * ctach문이 함수 try 블록에서 익셉션을 잡으면 생성자의 실행을 정상적으로 마친 베이스 클래스나 그 객체로 된 멤버는 ctach 문을 시작하기전에 소멸한다.<br><br>
  
  * catch문 안에서 객체로 된 멤버 변수에 접근하면 안된다.(catch문이 실행되기전에 소멸되기 때문)<br>
  그런데 익셉션이 발생하기 전에 그 객체에 논클래스 타입(ex)일반 포인터) 데이터 멤버를 초기화 했다면 접근할 수 있음<br>
  이런 리소스 정리 작업은 catch문에서 처리해야함<br><br>

  * 함수 try 블록에 있는 catch문은 그 안에 담긴 함수에서 값을 리턴할 때 return 키워드를 사용할 수 없다<br>
  생성잔는 원래 아무것도 리턴하지 않기 때문

<br>


* 함수 try 블록은 다음과 같은 제한된 상황에 적합하다

  * 생성자 이니셜라이저에서 던진 익셉션을 다른 익셉션으로 변환할 때
  
  * 메시지를 로그 파일에 기록할 때

  * 생성자 이니셜라이저에서 할당한,소멸자로 자동 제거할 수 없는 리소스를 익셉션에 던지기 전에 해제할 때

<br><br><br>

소멸자에서 익셉션을 처리하는 방법
=====================
* 소멸자에서 발생한 에러는 반드시 소멸자 안에서 처리해야 한다.(다른곳으로 던지면 안됨)

* 그 이유는 다음과 같다

  1. 소멸자를 명시적으로 noexcept(false)로 지정하지 않거나, 클래스에 있는 객체 중 소멸자에 noexcept(false)가 지정된 것이 없다면 내부적으로 noexcept로 선언된 것으로 취급한다.<br>
  noexcept 소멸자에서 익셉션을 던지면 C++런타임은 std::terminate()을 호출해서 프로그램 종료<br><br>

  2. 소멸자는 이미 다른 익셉션이 발생해서 스택 풀기를 수행하는 과정에서도 실행될 수 있다.<br>
    스택풀기 도중에 소멸자에서 익셉션을 던지면 C++ 런타임은 std::terminate()을 호출해서 종료<br>
    
  3. 클라이언트는 소멸자를 직접 호출하지 않고 delete를 통해 간접적으로 소멸자를 호출한다.<br>
  그런데 소멸자에서 익셉션을 던지면 이미 delete를 호출한 객체에 다시 delete를 호출할 수도 없고 소멸자를 직접 호출할 수도 없게 된다.<br><br>
  
  4. 소멸자는 객체에서 사용할 메모리나 리소스를 해제할 마지막 기회이므로, 함수 실행 도중에 익셉션을 던져 기회를 놓치면 다시 돌아가 메모리나 리소스를 해제할 수 없다.

