---
title: 에러 처리하기 - 2
date: 2023-02-07
categories: [C++,C++]
tags: [C++]		# TAG는 반드시 소문자로 이루어져야함!
---

익셉션 클래스 직접 정의하기
====================================
* 익셉션 클래스를 직접 정의하면 두 가지의 장점이 있다.
  
  * 익셉션 클래스를 직접 정의하면 runtime_error처럼 광범위한 이름 대신 발생한 에러에 최대한 가까운 이름으로<br> 표현할 수 있다.
  * 원하는 정보를 익셉션에 얼마든지 추가할 수 있다. 표준 라이브러리에서 제공하는 익셉션은 에러 스트링만 넣을 수 있다.

<br>

* 익셉션을 직접 정의할 때는 반드시 표준 exception 클래스를 직접 or 간접적으로 상속하는 것이 좋다.
  
  * 단, 이 원칙을 따르지 않는 서드파티 라이브러리가 있을 때는 X

<br><br><br><br>

* 파일 에러 클래스


<br>

    class FileError : public exception
    {
        public:
            FileError(string_view fileName) : mFileName(fileName) {}

        virtual const char* what() const noexcept override {
            return mMessage.c_str();
        }

        string_view getFileName() const noexcept { return mFileName; }

        protected:
            void setMessage(string_view message) { mMessage = message; }

        private:
            string mFileName;
            string mMessage;
    };

<br>

* exception 클래스를 상속하려면 what() 메서드를 오버라이드해야 한다.
    * 이 스트링은 익셉션 객체가 소멸되기 전까지 사용할 수 있다.

    * 이 스트링을 mMessage에 저장하고 파생 클래스에선 setMessage 메서드를 이용하여 다른 값으로 설정할 수 있다.

<br><br><br><br>

* 파일 열기 에러 클래스

<br>

    class FileOpenError : public FileError
    {
        public:
            FileOpenError(string_view fileName) : FileError(fileName)
            {
                setMessage("Unable to open"s + fileName.data());
            }
    };

<br>

* FileError 클래스를 상속한다.

* FileOpenError 익셉션은 파일 열기 에러를 표현하는 값을 mMessage에 저장

<br><br><br><br>

* 파일 읽기 에러 클래스

<br>

    class FileReadError : public FileError
    {
        public:
            FileReadError(string_view fileName, size_t lineNumber)
                : FileError(fileName) , mLineNumber(lineNumber)
            {
                ostringstream ostr;
                ostr << "Error reading " << fileName << " at line " << lineNumber; // 에러 줄 번호
                setMessage(ostr.str());
            }

            size_t getLineNumber() const noexcept { return mLineNumber; }
        
        private:
            size_t mLineNumber;
    }

<br>

* FileError 클래스를 상속한다.

* FileReadError 클래스는 파일이 열리지 않는 예외 상황을 위한 클래스

<br><br>

* 이렇게 작성한 FileError 클래스의 다형성을 이용하여 익셉션을 처리하는 catch 구문을 다음과 같이 작성할 수 있다.

<br>

    try {
        ...
    } catch (const FileError& e){
        ...
    }

<br>

* 익셉션이 발생하면 그 익셉션 객체를 이동 생성자나 복제 생성자로 이동하거나 복제하게 된다.

    * 익셉션 객체는 최소 한번 이상 이동하거나 복제된다.

    * 익셉션 객체를 레퍼런스로 받지 않으면 여러번 복제될 수 있다.
  
* 그래서 익셉션으로 사용할 클래스를 정의할 때는 객체를 복제하거나 이동할 수 있도록 만들어야한다.


<br><br><br>


중첩된 익셉션
================
* 익셉션을 처리하는 도중 다른 에러가 발생해 새로운 익셉션이 전달되면 현재 처리하고 있던 익셉션 정보는 사라진다.
  
* 먼저 잡은 익셉션을 새로 발생한 익셉션의 문맥 안에 포함시킬 수 있다.

<br><br><br>

* 예시

<br>

    // 클래스
    class MyException : public std::exception
    {
        public:
            MyException(string_view message) : mMessage(message) {}
            virtual const char* what() const noexcept override{
                return mMeesage.c_str();
            }

        private:
            string mMessage;            
    }

    =================

    // 함수
    void doSomething()
    {
        try{
            throw runtime_error("Throwing a runtime_error exception");
        } catch(const runtime_error& e){
            cout << __func__ << " caught a runtime error" << endl;
            cout << __func__ << " throwing MyException" << endl;
            throw_with_nested(
                MyException("MyException with nested runtime_error"));  // 새로운 익셉션을 throw
        }
    }

    ==================
    
    // main()

    int main()
    {
        try{
            doSomething();
        } catch(const MyException& e){
            cout << __func__ << " caught MyException: " << e.what() << endl;
            const auto* pNetsed = dynamic_cast<const nested_exception*>(&e);    // 이전 익셉션 접근

            if(pNested){
                try{
                    pNested->rethrow_nested();
                } catch(const runtime_error& e){
                    // 중첩된 익셉션 처리
                    cout << "Nested exception : << e.what() << endl;
                }
            }
        }
        return 0;
    }

<br>

* 어떤 익셉션을 처리하는 catch 문에서 새로운 익셉션을 던지려면 std::throw_with_netsed()를 이용한다.

* 나중에 발생한 익셉션을 처리하는 catch 문에서 먼저 발생했던 익셉션에 접근할 때는 dynamic_cast를 이용한다.

  * MyException을 처리하는 catch 핸들러로 dynamic_cast()를 이용하여 현재 익셉션에 중첩된 익셉션에 접근
  
  * 중첩된 익셉션이 없다면 널 포인트를 리턴
  
  * 중첩된 익셉션이 있다면 nested_exception의 rethrow_nested() 메서드를 호출해 다시 익셉션을 던져 다른 try/catch문에서 처리한다.

<br>

* rethrow_if_nested()라는 헬퍼 함수를 이용하여 중첩된 익셉션을 확인할 수도 있다

<br>

    // 아래와 위 모두 같은 동작
    const auto* pNetsed = dynamic_cast<const nested_exception*>(&e);
    if(pNested){
    try{
        pNested->rethrow_nested();
    } catch(const runtime_error& e)

    =====================

    try{
        rethrow_if_nested(e);
    } catch(const runtime_error& e);


<br>
<br><br><br>

스택 풀기와 청소
==============
* 익셉션을 던지면 받아서 처리할 catch 핸들러를 스택에서 찾으려 하는데 catch 핸들러는 스택 프레임에 있을수도 있고<br> 몇 단계의 함수 호출 스택을 거슬러 올라가야 있을 수도 있다.
  
* catch 핸들러를 발견하면 그 핸들러가 정의된 스택 단계로 되돌아가는데, 이 과정에서 중간단계에 있는 스택 프레임을 모두 푸는걸 "__스택풀기__"라 한다.<br>
  
  * 스코프가 로컬인 소멸자는 모두 호출하고, 각 함수에서 미처 실행하지 못한 코드는 건너뛴다.

<br><br><br>

* 스택 풀기가 발생할 때 포인터 변수를 해제하고 리소스를 정리하는 작업이 실행되지 않아 문제가 생길수도 있다.

<br>

    void funcOne();
    void funcTwo();
    
    int main()
    {
        try{
            funcOne();
        } catch(const exception& e){
            cerr << "Exception caught!" << endl;
            return 1;
        }
        return 0;
    }

    void funcOne()
    {
        string str1;
        string* str2 = new string();
        funcTwo();
        delete str2;
    }

    void funcTwo()
    {
        ifstream fileStream;
        fileStream.open("filename");
        throw exception();
        fileStream.close();
    }

<br>

* funcTwo 에서 익셉션을 던질 때 가장 가까운 핸들러는 main에 있다.
  
  * 그래서 funcTwo의 throw exception(); 문장에서 main의 cerr << "Exception caught!" << endl로 건너뛴다.<br>
  
  *  건너 뛰어버리면서 fileStream.close()가 실행되지 않는다

* ifStream는 스택에 있는 로컬변수라 소멸자가 호출되어 파일을 대신 닫아주므로 리소스 누수가 발생하지는 않는다.
  
* str1도 로컬 변수라 제대로 해제가 된다.

* delete str2는 실행되지 않아 메모리 누수가 발생한다.

<br><br><br><br>

스마트 포인터 활용
-----------
* 스택 기반 할당 방식을 사용할 수 없다면 스마트 포인터를 활용하여 메모리나 리소스를 자동으로 처리한다.

<br>

    void funcOne()
    {
        string str1;
        auto str2 = make_unique<string>("hello");
        funcTwo();
    }

<br>

* str2 포인터는 funcOne()을 호출한 후 리턴될 때 또는 그 안에서 익셉션이 발생할 때 자동으로 제거된다.

<br><br><br><br>

익셉션 잡고, 리소스 정리한 뒤,익셉션 다시 던지기
---------------------
* 메모리 및 리소스 누수 방지의 다른 기법은 각 함수마다 발생 가능한 익셉션을 모두 잡아서 리소스를 제대로 정리한뒤 <br> 그 익셉션을 다시 스택의 상위 핸들러로 던지는 것이다.

<br>

    void funcOne()
    {
        string str1;
        string* str2 = new string();
        try{
            funcTwo();
        } catch(...) {
            delete str2;
            throw; // funcTwo()에서 던져서 잡은 익셉션을 다시 위로 던진다.
        }
        delete str2;
    }

<br>

* 위의 방식보다는 되기는 하지만 스마트 포인터나 RAII 클래스를 사용하는 방법이 더 좋다.

