---
title: 에러 처리하기 - 1
date: 2023-02-06
categories: [C++,C++]
tags: [C++]		# TAG는 반드시 소문자로 이루어져야함!
---

익셉션
=====================
* 예외 상황이나 에러가 코드의 정상적인 실행 흐름에 퍼지지 않도록 알려주는 매커니즘
  
* 에러가 발생하면 익셉션을 던지고(throw), 이를 처리하는 코드는 발생한 익셉션을 받아서 처리(catch)한다.
  
* 익셉션을 던지면 프로그램의 정상 실행 흐름을 잠시 멈추고 익셉션 핸들러(예외 처리기)로 제어권을 넘긴다.

<br><br><br>

C++에서 익셉션이 필요한 이유
---------------------
* C나 C++ 프로그램을 보면 에러를 처리하는 방식이 제각각이고 체계가 없는 경우가 많다.
  
  * 함수가 정수코드를 리턴하거나 errno 매크로를 사용해 에러를 표시하는 등
  
<br>

* 에러 처리를 일관성 없이 구현한 함수들이 뒤섞이면 문제가 발생할 수 있다.
  * 호출한 함수가 예상과 다른 방식으로 코드를 리턴하기 때문

<br>

* 그리고 C++ 함수는 리턴 타입을 하나만 지정할 수 있어 에러와 결과 모두 리턴하려면 다른 수단이 필요하다.
  * ex) std::pair 나 std::tuple 에 결과와 에러를 같이 묶어서 리턴하는등

<br>

* 익셉션 매커니즘을 활용하면 에러를 쉽고 일관성 있고 안전하게 처리할 수 있다.
  
  * 에러를 리턴값으로 표현하면 호출한 측에서 깜박하고 리턴값을 검사하지 않거나 상위 함수로 전달하지 못할 수 있다.
   <br>반면 익셉션은 깜박 잊고 처리하지 않거나 무시할 수 없다. ( 처리하지않으면 프로그램이 멈춤)<br><br>

  * 에러를 정수 타입 리턴 코드로 표현하면 구체적인 정보를 담기 힘들다<br>
    반면 익셉션은 에러뿐만 아니라 다른 부가 정보도 담을 수 있다.<br><br>

  * 익셉션 매커니즘은 콜 스택의 중간 단계를 건너 뛸 수 있다.<br>
    다시 말해 여러 함수가 연속적으로 호출됐을 때 중간에 호출된 함수에서 에러를 처리하지 않고<br>  
    콜 스택의 최상위 함수에서 에러를 처리하게 만들 수 있다.<br>
    만약 리턴 코드를 활용한다면 함소 호출의 각 단계마다 반드시 에러 코드를 다음 단계로 전달해야한다.


<br><br><br>


익셉션 처리 과정
===============
* 표준 라이브러리나 부스트 같은 유명한 라이브러린는 익셉션을 적극 활용하고 있어 라이브러리를 사용하려면 익셉션을 다루는 방법을 잘 알아야 한다.


<br><br><br>

익셉션 던지고 받기
-----------------------
* 익셉션은 익셉션을 처리하는 try/catch문과 익셉션을 던지는 throw문 두 부분으로 나뉜다.



* 대부분의 라이브러리들에서 throw문은 라이브러리 깊숙한 곳에 있어 프로그래머가 직접 볼 수 없을 때가 많지만,<br> try/catch문은 따로 작성해줘야 한다.

<br><br>

* try / catch문의 구성

<br>

    try{
      // 익셉션이 발생할 수 있는 코드
    } catch (익셉션_타입1 익셉션_이름){
      // 익셉션_타입1 익셉션을 처리하는 코드
    } catch (익셉션_타입2 익셉션_이름){
      // 익셉션_타입2 익셉션을 처리하는 코드
    }

<br>

* 예외 상황이 발생할 수 있는 코드에 throw 문에 익셉션을 직접 던져도 된다.
* 또한 throw문으로 익셉션을 직접 던지건나 익셉션을 던지는 함수를 호출하는 문장이 담긴 함수를 호출할 수도 있다.

<br><br>

* 0으로 나눈 상황을 감시하는 함수

<br>

    double SafeDivide(double num , double den)
    {
        if (0 == den)
            throw invalid_argument("Divde by zero");
        
        return num / den;
    }

    int main()
    {
      try{
        cout<< SafeDivide(5,2) << endl;
        cout<< SafeDivide(10,0) << endl;
        cout<< SafeDivide(3,3) << endl;
      } catch (const invalid_argument& e){
        cout<< "Caught exception: " << e.what() << endl;
      }
      return 0;
    }

    // 결과
    2.5
    Caught exception: Divde by zero

<br>

* throw문에 나온 invalid_argument()는 던질 invalid_argument 타입의 익셉션 객체를 생성한다.

  * invalid_argument는 C++ 표준 라이브러리에서 제공하는 표준 익셉션 중 하나

<br>

* 표준 라이브러리에 정의된 익셉션은 일정한 계층을 형성하고 있다.

<br>

* 이 계층 구조에 속한 클래스마다 what() 메서드가 있는데, 이 메서드는 익셉션을 표현하는 const char* 스트링을 리턴한다.
  * 이 값은 익셉션 생성자의 인수로 전달하는 방식으로 설정한다.

<br><br>

* 파일 입출력 과정에서의 익셉션 처리

<br>

    vector<int> readIntegerFile(string_view fileName)
    {
        ifstream inputStream(fileName.data());
        // 파일에 담긴 정수값을 하나씩 읽어서 벡터에 추가

        if(inputStream.fail())
          throw exception();  // 파일 열기 실패 : 익셉션을 던진다.


        vector<int> integers;
        int temp;
        while (inputStream >> temp)
        {
            integers.push_back(temp);
        }
        return integers;
    }

    ////
    int main()
    {
        const string fileName = "IntegerFile.txt";
        vector<int> myInts;
        try{
          myInts = readIntegerFile(fileName);
        } catch (const exception& e){
          cerr << "Unable to open file " << fileName <<endl;
          return 1;
        }
        for (const auto& element : myInts)
        { 
            cout << element << " ";
        }
        cout << endl;
        return 0;
    }

<br>

* \>> 연산을 수행할 때 에러가 발생하면 ifstream 객체에 에러 플래그가 설정된다.

* 그러면 bool() 변환 연산자가 false를 리턴하면서 while 루프가 종료된다.

* 파일을 열 때 에러가 발생할 경우 std::exception 타입으로 익셉션을 생성한다.


<br><br><br>

익셉션 타입
------------------
* 던질  수 있는 익셉션의 타입에는 제한이 없다

* 하지만 기본 타입을 사용하기 보다는 새로 정의하는 것이 바람직하다.그 이유는 다음과 같다.
  * 객체의 클래스 이름에 예외 상황에 대한 정보를 드러낼 수 있다.
  * 예외 상황의 종류뿐만 아니라  다른 정보도 담을 수 있다.

<br>

* C++ 표준 라이브러리에 정의돼 있는 익셉션 클래스를 활용하거나, 익셉션 클래스를 직접 정의할 수도 있다.

<br><br><br>

여러 가지 익셉션 던지고 받기
----------------------

<br>

* 위에서의 파일 입출력 과정에서의 익셉션 처리 예시

<br>

    // readIngerFile 함수 안
    if(inputStream.fail())
        throw invalid_argument("Unable to open the file.");

    ..

    if(!inputStream.eof()){
        // 파일의 끝에 도달하지 않았다.
        // 다시 말해 파일을 읽는 도중 에러 발생으로 익셉션을 던짐
        throw runtime_error("Error reading the file");
    }

    ==========
    int main()
    {
        ...
        try{
            myInts = readIntegerFile(fileName);
        } catch (const invalid_argument& e){
            cerr << e.what() << endl;
            return 1;
        } catch (const runtime_error& e){
            cerr << e.what() << endl;
            return 2;
        }
    }

<br>

* 파일을 열수 없으면 invalid_argument 익셉션을 던지고, 정수를 읽을 수 없으면 runtime_error 익셉션을 던진다.

* runtime_error와 invalid_argument 둘다 C++ 표준 라이브러리인 \<stdexcept> 헤더 파일에 있다.

* runtime_error와 invalid_argument는 public 디폴트 생성자가 없고 string 인수를 받는 생성자만 있다.

* try블록에서는 익셉션 타입과 일치하는 catch문(핸들러)을 선택한다.


<br><br><br><br>

익셉션 타입 매칭과 const
-----------------------
* 처리하는 익셉션 타입에 const가 지정됐는지 여부는 매칭 과정에 영향을 미치지 않는다.
* 예를 들어 다음 문장은 runtime_error 타입에 속하는 모든 익셉션을 매칭한다.

<br>

    // 둘 다 runtime_error 타입에 속하는 모든 익셉션을 매칭
    } catch (const runtime_error& e)
    } catch (runtime_error& e)

<br>

<br><br><br><br>

모든 익셉션 매칭하기
----------------
* catch문에서 모든 종류의 익셉션에 매칭하려면 다음과 같이 작성한다.

<br>

    } catch (...){

<br>

* ...은 모든 익셉션 타입에 매칭
  
* if문의 else처럼 사용할 수 있다.

<br><br><br><br>

처리하지 못한 익셉션
---------------
* 프로그램에서 발생한 익셉션을 처리하는 곳이 하나도 없으면 프로그램이 종료돼버린다.
  
* 그래서 처리하지 못한 익셉션을 모두 잡도록 main() 함수 전체를 try/catch 구문으로 감싸는 패턴을 사용할 수도  있다.

<br>

    try{
        main(argc, argv);
    } catch(...){
      ...
    }

<br><br>

* 프로그램이 잡지 못한 익셉션을 만나면 terminate() 함수를 호출하게 만들 수도 있다.
  
* 이 함수는 C++에서 기본으로 제공하며, 내부적으로 \<cstdlib>헫더에 정의된 abort() 함수를 호출한다.
  
* 또는 set_terminate()에 인수를 받지 않고 리턴값도 없는 콜백 함수를 포이넡로 지정하는 방식으로 terminate_handler를 직접 구현해도 된다.

<br>

    try{
        main(argc, argv);
    } catch(...){
        if(nullptr != terminate_handler){
            terminate_handler();
        } else {
            terminate();
        }
    }

<br>

<br><br>

* 위와 같이 작성하면 결국 에러를 무시하지 못하고 프로그램을 종료시켜버린다.

* 그래서 종료 직전에 유용한 정보를 담은 에러메세지를 출력할 방법도 있다.

<br>

    void myTerminate()
    {
        cout <<"Uncaught exception!" << endl;
        exit(1);
    }

    // set_terminate은 새로운 핸들러를 지정하면 기존에 설정된 핸들러는 리턴한다
    int main(){
        set_terminate(myTerminate); 
        ...
    }

<br>

* 프로세스를 종료하는 방식으로 정숫값을 인수로 받고 OS로 전달

<br><br><br><br>

noexcept
-------------
* 함수가 던질 수 있는 익셉션의 종류에는 제한이 없지만, noexcept 키워드로 어떠한 익셉션도 던지지 않는다고 지정할 수 있다.

<br>

    vector<int> readIntegerFile(string_view fileName) noexcept;

<br>

* noexcept 키워드가 지정된 함수에 익셉션을 던지는 코드가 있다면 C++ 런타임은 terminate()을 호출하여 프로그램을 종료시킨다.

* 파생 클래스에서 virtual 메서드를 오버라이드할 때 베이스 클래스의 메서드에 noexcept가 지정되지 않더라도<br> 오버라이드하는 메서드에 noexcept를 지정할 수 있다. (반대는 불가능)

<br><br><br><br>

